Workbook

Sheet Projet
A1: Projet Sarnois | B1: IND06 | C1: IND07 | D1: IND08 | E1: IND09 | F1: IND10A | G1: IND10B
A2: Phase | B2: APD | C2: APD | D2: APD | E2: APD | F2: APD | G2: APD
A3: Date (jj/mm/aaaa) | B3: 46153 | C3: 46154 | D3: 46168 | E3: 46225 | F3: 46261 | G3: 46261
A6: GENERALITES
A7: Type de projet | B7: Ovin | C7: Ovin | D7: Ovin | E7: Ovin | F7: Ovin | G7: Ovin
A8: Surface clôturée (ha) | B8: 12.99 | C8: 12.93 | D8: 12.93 | E8: 12.93 | F8: 4.87 | G8: 3.48
A9: Linéaire de clôture (m) | B9: 1805 | C9: 1800 | D9: 1802 | E9: 1803 | F9: 949 | G9: 738
A10: Nombre de portails d'accès | B10: 2 | C10: 2 | D10: 2 | E10: 2 | F10: 1 | G10: 1
A11: Largeur des portails (m) | B11: 7 | C11: 7 | D11: 7 | E11: 7 | F11: 7 | G11: 7
A13: SYSTÈME PHOTOVOLTAÏQUE
A14: Structures PV
A15: Type de structure | B15: Fixe | C15: Fixe | D15: Fixe | E15: Fixe | F15: Fixe | G15: Fixe
A16: Format table | B16: 2V13/2V6 | C16: 2V26/2V6 | D16: 2V26/2V13 | E16: 2V26/2V13 | F16: 2V26/2V13 | G16: 2V26/2V13
A17: Inclinaison (°) | B17: =HLOOKUP($B$7,'Standards UNITe'!$C$3:$L$8,3,0) -> 25 | C17: =HLOOKUP($B$7,'Standards UNITe'!$C$3:$L$8,3,0) -> 25 | D17: =HLOOKUP($B$7,'Standards UNITe'!$C$3:$L$8,3,0) -> 25 | E17: =HLOOKUP($B$7,'Standards UNITe'!$C$3:$L$8,3,0) -> 25 | F17: =HLOOKUP($B$7,'Standards UNITe'!$C$3:$L$8,3,0) -> 25 | G17: =HLOOKUP($B$7,'Standards UNITe'!$C$3:$L$8,3,0) -> 25
A18: Azimut (°) | B18: -24.5 | C18: -24.5 | D18: -24.5 | E18: -24.5 | F18: -24.5 | G18: -24.5
A19: Nombre de tables | B19: 537 & 59 | C19: 485 & 69 | D19: 265 & 35 | E19: 269 & 27 | F19: 84 & 1 | G19: 79 & 11
A20: Inter-table (m) | B20: 6 | C20: 6 | D20: 5 | E20: 5 | F20: 6 | G20: 5
A21: Pitch (m) | B21: 10.3 | C21: 10.3 | D21: 9.3 | E21: 9.3 | F21: 10.3 | G21: 9
A22: Point bas (m) | B22: =HLOOKUP($B$7,'Standards UNITe'!$C$3:$L$12,8,0) -> 1.5 | C22: =HLOOKUP($B$7,'Standards UNITe'!$C$3:$L$12,8,0) -> 1.5 | D22: =HLOOKUP($B$7,'Standards UNITe'!$C$3:$L$12,8,0) -> 1.5 | E22: =HLOOKUP($B$7,'Standards UNITe'!$C$3:$L$12,8,0) -> 1.5 | F22: =HLOOKUP($B$7,'Standards UNITe'!$C$3:$L$12,8,0) -> 1.5 | G22: =HLOOKUP($B$7,'Standards UNITe'!$C$3:$L$12,8,0) -> 1.5
A23: Point haut (m) | B23: 3.53 | C23: 3.53 | D23: 3.53 | E23: 3.53 | F23: 3.53 | G23: 3.53
A24: Nb de mod en rampant | B24: 2 | C24: 2 | D24: 2 | E24: 2 | F24: 2 | G24: 2
A25: Nb de mod en longueur | B25: 13 & 6 | C25: 13 & 6 | D25: 13 & 26 | E25: 13 & 26 | F25: 13 & 26 | G25: 13 & 26
A26: Nb de mod/string | B26: 26 | C26: 26 | D26: 26 | E26: 26 | F26: 26 | G26: 26
A27: Nb de mod/table | B27: 26 | C27: 26 | D27: 26 | E27: 26/52 | F27: 26/52 | G27: 26/52
A28: Type de fondation | B28: Pieux battus | C28: Pieux battus | D28: Pieux battus | E28: Pieux battus | F28: Pieux battus | G28: Pieux battus
A29: Nombre de pieux | B29: =537*10+59*6 -> 5724 | C29: =485*10+69*6 -> 5264 | D29: =265*9+35*5 -> 2560 | E29: =269*9+27*5 -> 2556 | F29: =84*9+1*5 -> 761 | G29: =79*9+11*5 -> 766
A30: Surface pieux (m²) | B30: =B29*IF(B15="Flotteur",0,IF(OR(B7="Volailles",B7="Faisans",B7="Parking"),VLOOKUP(B28,'Dimensions postes et pieux'!$O$5:$P$8, 2, 0),VLOOKUP(B28,'Dimensions postes et pieux'!$O$9:$P$12, 2, 0))) -> 40.068 | C30: =C29*IF(C15="Flotteur",0,IF(OR(C7="Volailles",C7="Faisans",C7="Parking"),VLOOKUP(C28,'Dimensions postes et pieux'!$O$5:$P$8, 2, 0),VLOOKUP(C28,'Dimensions postes et pieux'!$O$9:$P$12, 2, 0))) -> 36.848 | D30: =D29*IF(D15="Flotteur",0,IF(OR(D7="Volailles",D7="Faisans",D7="Parking"),VLOOKUP(D28,'Dimensions postes et pieux'!$O$5:$P$8, 2, 0),VLOOKUP(D28,'Dimensions postes et pieux'!$O$9:$P$12, 2, 0))) -> 17.92 | E30: =E29*IF(E15="Flotteur",0,IF(OR(E7="Volailles",E7="Faisans",E7="Parking"),VLOOKUP(E28,'Dimensions postes et pieux'!$O$5:$P$8, 2, 0),VLOOKUP(E28,'Dimensions postes et pieux'!$O$9:$P$12, 2, 0))) -> 17.892 | F30: =F29*IF(F15="Flotteur",0,IF(OR(F7="Volailles",F7="Faisans",F7="Parking"),VLOOKUP(F28,'Dimensions postes et pieux'!$O$5:$P$8, 2, 0),VLOOKUP(F28,'Dimensions postes et pieux'!$O$9:$P$12, 2, 0))) -> 5.327 | G30: =G29*IF(G15="Flotteur",0,IF(OR(G7="Volailles",G7="Faisans",G7="Parking"),VLOOKUP(G28,'Dimensions postes et pieux'!$O$5:$P$8, 2, 0),VLOOKUP(G28,'Dimensions postes et pieux'!$O$9:$P$12, 2, 0))) -> 5.362
A31: Modules PV
A32: Format | B32: G12R | C32: G12R | D32: G12R | E32: G12R | F32: G12R | G32: G12R
A33: Puissance unitaire (Wc) | B33: 680 | C33: 680 | D33: 680 | E33: 680 | F33: 680 | G33: 680
A34: Surface unitaire (m²) | B34: =IF(B32="G12R", 2.382*1.134, 2.382*1.303) -> 2.701188 | C34: =IF(C32="G12R", 2.382*1.134, 2.382*1.303) -> 2.701188 | D34: =IF(D32="G12R", 2.382*1.134, 2.382*1.303) -> 2.701188 | E34: =IF(E32="G12R", 2.382*1.134, 2.382*1.303) -> 2.701188 | F34: =IF(F32="G12R", 2.382*1.134, 2.382*1.303) -> 2.701188 | G34: =IF(G32="G12R", 2.382*1.134, 2.382*1.303) -> 2.701188
A35: Nombre installé | B35: 14670 | C35: 13348 | D35: 14690 | E35: 14690 | F35: 4394 | G35: 4394
A36: GCR (%) | B36: =4.34/10.3 -> 0.42135922 | C36: =4.34/10.3 -> 0.42135922 | D36: / | E36: / | F36: / | G36: /
A37: Surface modules (m²) | B37: =IFERROR(B34*B35,"-") -> 39626.428 | C37: =IFERROR(C34*C35,"-") -> 36055.457 | D37: =IFERROR(D34*D35,"-") -> 39680.452 | E37: =IFERROR(E34*E35,"-") -> 39680.452 | F37: =IFERROR(F34*F35,"-") -> 11869.02 | G37: =IFERROR(G34*G35,"-") -> 11869.02
A38: Surface module projetée au sol (m²) | B38: =IFERROR(B37*COS(RADIANS(B17)),"-") -> 35913.74 | C38: =IFERROR(C37*COS(RADIANS(C17)),"-") -> 32677.342 | D38: =IFERROR(D37*COS(RADIANS(D17)),"-") -> 35962.702 | E38: =IFERROR(E37*COS(RADIANS(E17)),"-") -> 35962.702 | F38: =IFERROR(F37*COS(RADIANS(F17)),"-") -> 10756.985 | G38: =IFERROR(G37*COS(RADIANS(G17)),"-") -> 10756.985
A39: Puissance projet (MWc) | B39: =IFERROR(B33*B35/1000000,"-") -> 9.9756 | C39: =IFERROR(C33*C35/1000000,"-") -> 9.07664 | D39: =IFERROR(D33*D35/1000000,"-") -> 9.9892 | E39: =IFERROR(E33*E35/1000000,"-") -> 9.9892 | F39: =IFERROR(F33*F35/1000000,"-") -> 2.98792 | G39: =IFERROR(G33*G35/1000000,"-") -> 2.98792
A42: POSTES ELEC. ET LOCAUX TECHNIQUES
A43: Postes élec.
A44: Type d'onduleurs envisagés | B44: String | C44: String | D44: String | E44: String | F44: String | G44: String
A45: Nombre de PTR | B45: 2 | C45: 2 | D45: 2 | E45: 2 | F45: 0 | G45: 0
...

Sheet Feuil1
G1: Projet Sarnois | H1: IND10A
G2: Phase | H2: APD
G3: Date (jj/mm/aaaa) | H3: 46261
G6: GENERALITES
G7: Type de projet | H7: Ovin
G8: Surface clôturée (ha) | H8: 4.87
G9: Linéaire de clôture (m) | H9: 949
G10: Nombre de portails d'accès | H10: 1
G11: Largeur des portails (m) | H11: 7
G13: SYSTÈME PHOTOVOLTAÏQUE
G14: Structures PV
G15: Type de structure | H15: Fixe
G16: Format table | H16: 2V26/2V13
G17: Inclinaison (°) | H17: 25
G18: Azimut (°) | H18: -24.5
G19: Nombre de tables | H19: 84 & 1
G20: Inter-table (m) | H20: 6
G21: Pitch (m) | H21: 10.3
G22: Point bas (m) | H22: 1.5
G23: Point haut (m) | H23: 3.53
G24: Nb de mod en rampant | H24: 2
G25: Nb de mod en longueur | H25: 13 & 26
G26: Nb de mod/string | H26: 26
G27: Nb de mod/table | H27: 26/52
G28: Type de fondation | H28: Pieux battus
G29: Nombre de pieux | H29: 761
G30: Surface pieux (m²) | H30: 5.327
G31: Modules PV
G32: Format | H32: G12R
G33: Puissance unitaire (Wc) | H33: 680
G34: Surface unitaire (m²) | H34: 2.701188
G35: Nombre installé | H35: 4394
G36: GCR (%) | H36: /
G37: Surface modules (m²) | H37: 11869.02
G38: Surface module projetée au sol (m²) | H38: 10756.985
G39: Puissance projet (MWc) | H39: 2.98792
G42: POSTES ELEC. ET LOCAUX TECHNIQUES
G43: Postes élec.
G44: Type d'onduleurs envisagés | H44: String
G45: Nombre de PTR | H45: 0
...

Sheet Détails AgriPV
D3: Parcelle 1 | E3: Parcelle 2
C4: Surface PV (m²) | D4: =1846*(2.382*1.134)*COS(RADIANS(Projet!$F$17)) -> 4519.2068 | E4: =2548*(2.382*1.134)*COS(RADIANS(Projet!$F$17)) -> 6237.7785
C5: Parcelle agricole (m²) | D5: 9955 | E5: 14454
C6: Surface cloturé parcelle (ha) | D6: =Projet!F8 -> 4.87
C7: Fondations
C8: Nombre de pieux | D8: =35*9+1*5 -> 320 | E8: =49*9+8*5 -> 481
C9: Surface pieux (m²) | D9: =0.007*D8 -> 2.24 | E9: =0.007*E8 -> 3.367
C10: Surface pieux + 20cm (m²) | D10: =0.2*D8 -> 64 | E10: =0.2*E8 -> 96.2
C11: Postes élec.
C12: Surface plateforme PTR (m²) | D12: 0 | E12: 0
C13: Surface plateforme PDL/PTR (m²) | D13: 132 | E13: 0
C14: Aire de charge (BESS)
C15: Surface conteneurs batteries (m²) | D15: =18*2 -> 36 | E15: 0
C16: Surface plateforme PTR (m²) | D16: 115 | E16: 0
C17: Surface zone de remise (m²) | D17: =1*36 -> 36 | E17: 0
C18: Surface citerne de refroidissement (m²) | D18: =1*104 -> 104 | E18: 0
C19: Autre
C20: Surface citerne incendie (m²) | D20: 104 | E20: 0
C21: Surface local de stockage matériel (m²) | D21: 18 | E21: 0
C22: Surface pistes lourdes (m²) | D22: 1280
C23: Données agriPV
C24: Total surface non exploitable (ha) | D24: =SUM(D10:E22)/10000 -> 0.19852
C25: Total surface non exploitable (%) | D25: =D24/SUM(D6:E6) -> 0.04076386
C26: Taux de couverture (%) | D26: =D4/D5 -> 0.45396352 | E26: =E4/E5 -> 0.43156071
C28: Calcul de la surface non exploitable pour agriPV culture Contacter la Chambre d'Agriculture pour connaître la formule à appliquer (par rapport à quelle surface ? Quel retrait par rapport aux pieux ?) C'est au chef de projet de mofifier la formule de calcul dans l'Excel.

Sheet Standards UNITe
B2: Type de projet | C2: PV sol | G2: Ombrières | J2: Flottant | K2: Trackers
B3: Type d'activité | C3: 1MWc | D3: Agri compatible | E3: Ovin | F3: Bovin | G3: Faisans | H3: Volailles | I3: Parking | J3: Flottant | K3: AgriPV élevage ou prairie | L3: AgriPV grande culture
B4: Format modules | C4: G12R | D4: G12R | E4: G12R | F4: G12R | G4: G12R | H4: G12R | I4: G12R | J4: G12R | K4: G12R | L4: G12R
B5: Inclinaison | C5: 15 | D5: 15 | E5: 25 | F5: 15 | G5: 10 | H5: 10 | I5: 10 | J5: 5 | K5: 0 | L5: 0
B6: Azimut | C6: 0° | D6: 0° | E6: 0° | F6: 0° | G6: 0° | H6: 0° | I6: 0° | J6: 0° | K6: 90° | L6: 90°
B7: Orientation | C7: portrait | D7: portrait | E7: portrait | F7: portrait | G7: portrait | H7: portrait | I7: portrait | J7: paysage | K7: portrait | L7: portrait
B8: Types de tables (portrait = V, paysage = H) | C8: 2V | D8: 3V | E8: 2V | F8: 2V | G8: 7V | H8: 6V | I8: 11V | J8: 1H | K8: 1V | L8: 2V
B9: Distance inter-table | C9: 3 | D9: 4 | E9: 8 | F9: 8 | G9: 12 | H9: 12 | I9: 6 | J9: 0,75 m | K9: 5.1 | L9: 8.2
B10: Hauteur point bas | C10: 1.1 | D10: 1.1 | E10: 1.5 | F10: 2.5 | G10: 2.5 | H10: 2.5 | I10: 3 | J10: N/A | K10: 1.1 | L10: 1.1
B11: Hauteur point haut | C11: 2.34 | D11: 2.34 | E11: 3.12 | F11: 3.74 | G11: 5.42 | H11: 5 | I11: 7.58 | J11: N/A | K11: N/A | L11: N/A
B12: Setback | C12: 5 | D12: 5 | E12: 10 | F12: 10 | G12: 5 | H12: 5 | I12: 6 | J12: 15 m par rapport aux berges | K12: 10 | L12: 10

Sheet Dimensions postes et pieux
C3: Poste de transformation - PTR | G3: -> Onduleurs et transformateur dans le même poste | O3: Fondations
C4: Dimensions (largeur x longueur x hauteur) | D4: Surface (m²) | E4: Surface plateforme (m²) | N4: Projet | O4: Type | P4: Surface (m²)
C5: 10 x 3 x 3m | D5: 30 | E5: 115 | N5: Faisans / Volaille / Parking | O5: Pieux battus | P5: 0.16
O6: +20cm | P6: 0.45
O7: Pieux Forage/Battus | P7: 0.16
O8: Longrine
C9: Transformateur - PT | G9: -> Transformateur seul dans son poste | N9: Autre | O9: Pieux battus | P9: 0.007
C10: Dimensions (largeur x longueur x hauteur) | D10: Surface (m²) | E10: Surface plateforme (m²) | O10: +20cm | P10: 0.2
C11: 6 x 3 x 3m | D11: 18 | E11: 50 | O11: Pieux Forage/Battus | P11: 0.04
O12: Longrine | P12: 0.9
C15: Poste de livraison et de transformation - PDL/PTR | G15: ->Transformateur et cellules d'arrivée Enedis dans le même poste
C16: Dimensions (longueur x largeur x hauteur) | D16: Surface (m²) | E16: Surface plateforme (m²)
C17: 12 x 3 x 3m | D17: 36 | E17: 132
C21: Poste de livraison - PDL | G21: -> Pas de transformateur dans le poste
C22: Dimensions (longueur x largeur x hauteur) | D22: Surface (m²) | E22: Surface plateforme (m²)
C23: 9 x 3 x 3m | D23: 27 | E23: 110 | G23: -> Plus de limite de surface de plancher pour les DP
C27: Aire de charge (BESS)
C28: Dimensions (longueur x largeur x hauteur) | D28: Surface (m²) | E28: Surface plateforme (m²)
B29: Conteneurs | C29: 6 x 3 x 3m | D29: 18 | E29: 50
B30: PTR | C30: 10 x 3 x 3m | D30: 30 | E30: 115
B31: Citerne de refroidissement | C31: 11,7 x 9,3 x 1 m | D31: 104
B32: Bac de rétention | C32: 17,5 x 3 x 2,3 m | D32: 53
B33: Zone de remise | C33: 12 x 3 x 3m | D33: 36
C37: Local de stockage matériel
C38: Dimensions (longueur x largeur x hauteur) | D38: Surface (m²)
B39: P<=5MWc | C39: 1 conteneur 20 pieds 6 x 3 x 3m | D39: 18
B40: P>5MWc | C40: 1 conteneur 40 pieds 12 x 3 x 3m | D40: 36
B41: P>17MWc | C41: 2 conteneurs 40 pieds 12 x 3 x 3m | D41: 72
B45: Citerne incendie
B46: Volume [m3] | C46: Dimensions (longueur x largeur x hauteur) | D46: Surface plateforme (m²)
B47: 30 | C47: 7,95 x 4,44 x 1,3 m | D47: 35
B48: 60 | C48: 8,1 x 7,4 x 1,5 m | D48: 60
B49: 120 | C49: 11,7 x 9,3 x 1 m | D49: 104
B50: 240 | C50: 10,4 x 18,5 x 1,6 m | D50: 192
B51: Compter une aire d'aspiration de 32m² (8 x 4m)
F53: Zone de stockage
E54: Fixe | F54: +270m²/2,5MWc
C55: Base vie | E55: Tracker | F55: +350m²/2,5MWc
C56: Surface conseillée (m²)
B57: P <= 10MWc | C57: 1500 | F57: Zone logistique
...

Sheet Batteries de stockage
D3: POUR TOUS LES PROJETS
D4: Conteneur 20 pieds (6x3x3m) | E4: PTR
C5: P<=20MWc | D5: x4 | E5: x2
C6: P>20MWc | D6: x8 | E6: x4
B9: Règles ICPE
B10: Implantation à 12m de la clôture
B11: Equipements espacés de 7m les uns par rapport aux autres
B13: PROJETS A ENJEUX
B14: 1 conteneur 20 pieds et 1 PTR associé (capacité 5MWh)

Sheet Revue APS
C3: =Projet!A1 -> Projet Sarnois
C5: Chargé de projet - dév :
C6: Chargé de projet - étude : | E6: NFE
C8: Design
C9: Pnom | F9: Productible PVSyst | I9: Performance Ratio (PR) | L9: Production (P50)
C10: =OFFSET(Projet!B39,0,MATCH(MAX(Projet!B39:Y39)+1,Projet!B39:Y39,1)-1) -> 2.98792 | F10: =OFFSET(Projet!B160,0,MATCH(MAX(Projet!B160:Y160)+1,Projet!B160:Y160,1)-1) -> 1138 | I10: =OFFSET(Projet!B161,0,MATCH(MAX(Projet!B161:Y161)+1,Projet!B161:Y161,1)-1) -> 0.8815 | L10: =OFFSET(Projet!B162,0,MATCH(MAX(Projet!B162:Y162)+1,Projet!B162:Y162,1)-1) -> 3.400253
J12: Documents à disposition
J13: Topo Drone : | K13: TRUE | L13: DT : | M13: TRUE
J14: Plan de masse : | K14: TRUE | L14: Rés. Privés : | M14: TRUE
J15: Plan de coupe : | K15: TRUE | L15: Dép Ouvr GRD :
J16: PVSyst : | K16: TRUE | L16: Unifilaire :
J19: Module APD
J20: Dim (mm) : | K20: 2382x1134x30 | L20: Puissance : | M20: =OFFSET(Projet!B33,0,MATCH(MAX(Projet!B33:Y33)+1,Projet!B33:Y33,1)-1) -> 680
J21: Techno : | K21: TopCon | L21: .pan : | M21: FALSE
J22: Date 1er Livraison : | K22: Q3 2030
